Workbook

Sheet Зведення
A1: LuxSite: роботи, які ToDo виконала, але не виставила клієнту
A2: Стан табеля: живий Odoo, проєкт 55, 05.10.2026. Суми в грн без ПДВ, орієнтовно.
A4: Рік | B4: Табель: факт > виставлено, год | C4: Без рядків у табелі, год | D4: Разом, год | E4: Табель, грн | F4: Без рядків, грн | G4: Разом, грн
A5: 2023 | B5: =SUMIFS(Табель_55!$J$2:$J$278,Табель_55!$C$2:$C$278,A5) | C5: =SUMIFS(Без_рядків!$H$2:$H$67,Без_рядків!$C$2:$C$67,A5) | D5: =B5+C5 | E5: =SUMIFS(Табель_55!$M$2:$M$278,Табель_55!$C$2:$C$278,A5) | F5: =SUMIFS(Без_рядків!$K$2:$K$67,Без_рядків!$C$2:$C$67,A5) | G5: =E5+F5
A6: 2024 | B6: =SUMIFS(Табель_55!$J$2:$J$278,Табель_55!$C$2:$C$278,A6) | C6: =SUMIFS(Без_рядків!$H$2:$H$67,Без_рядків!$C$2:$C$67,A6) | D6: =B6+C6 | E6: =SUMIFS(Табель_55!$M$2:$M$278,Табель_55!$C$2:$C$278,A6) | F6: =SUMIFS(Без_рядків!$K$2:$K$67,Без_рядків!$C$2:$C$67,A6) | G6: =E6+F6
A7: 2025 | B7: =SUMIFS(Табель_55!$J$2:$J$278,Табель_55!$C$2:$C$278,A7) | C7: =SUMIFS(Без_рядків!$H$2:$H$67,Без_рядків!$C$2:$C$67,A7) | D7: =B7+C7 | E7: =SUMIFS(Табель_55!$M$2:$M$278,Табель_55!$C$2:$C$278,A7) | F7: =SUMIFS(Без_рядків!$K$2:$K$67,Без_рядків!$C$2:$C$67,A7) | G7: =E7+F7
A8: 2026 | B8: =SUMIFS(Табель_55!$J$2:$J$278,Табель_55!$C$2:$C$278,A8) | C8: =SUMIFS(Без_рядків!$H$2:$H$67,Без_рядків!$C$2:$C$67,A8) | D8: =B8+C8 | E8: =SUMIFS(Табель_55!$M$2:$M$278,Табель_55!$C$2:$C$278,A8) | F8: =SUMIFS(Без_рядків!$K$2:$K$67,Без_рядків!$C$2:$C$67,A8) | G8: =E8+F8
A9: РАЗОМ | B9: =SUM(B5:B8) | C9: =SUM(C5:C8) | D9: =SUM(D5:D8) | E9: =SUM(E5:E8) | F9: =SUM(F5:F8) | G9: =SUM(G5:G8)
A11: По місяцях
A12: Місяць | B12: Табель, год | C12: Без рядків, год | D12: Разом, год | E12: Табель, грн | F12: Без рядків, грн | G12: Разом, грн
A13: 2023-04 | B13: =SUMIFS(Табель_55!$J$2:$J$278,Табель_55!$D$2:$D$278,A13) | C13: =SUMIFS(Без_рядків!$H$2:$H$67,Без_рядків!$D$2:$D$67,A13) | D13: =B13+C13 | E13: =SUMIFS(Табель_55!$M$2:$M$278,Табель_55!$D$2:$D$278,A13) | F13: =SUMIFS(Без_рядків!$K$2:$K$67,Без_рядків!$D$2:$D$67,A13) | G13: =E13+F13
A14: 2023-05 | B14: =SUMIFS(Табель_55!$J$2:$J$278,Табель_55!$D$2:$D$278,A14) | C14: =SUMIFS(Без_рядків!$H$2:$H$67,Без_рядків!$D$2:$D$67,A14) | D14: =B14+C14 | E14: =SUMIFS(Табель_55!$M$2:$M$278,Табель_55!$D$2:$D$278,A14) | F14: =SUMIFS(Без_рядків!$K$2:$K$67,Без_рядків!$D$2:$D$67,A14) | G14: =E14+F14
A15: 2023-06 | B15: =SUMIFS(Табель_55!$J$2:$J$278,Табель_55!$D$2:$D$278,A15) | C15: =SUMIFS(Без_рядків!$H$2:$H$67,Без_рядків!$D$2:$D$67,A15) | D15: =B15+C15 | E15: =SUMIFS(Табель_55!$M$2:$M$278,Табель_55!$D$2:$D$278,A15) | F15: =SUMIFS(Без_рядків!$K$2:$K$67,Без_рядків!$D$2:$D$67,A15) | G15: =E15+F15
A16: 2023-07 | B16: =SUMIFS(Табель_55!$J$2:$J$278,Табель_55!$D$2:$D$278,A16) | C16: =SUMIFS(Без_рядків!$H$2:$H$67,Без_рядків!$D$2:$D$67,A16) | D16: =B16+C16 | E16: =SUMIFS(Табель_55!$M$2:$M$278,Табель_55!$D$2:$D$278,A16) | F16: =SUMIFS(Без_рядків!$K$2:$K$67,Без_рядків!$D$2:$D$67,A16) | G16: =E16+F16
A17: 2023-08 | B17: =SUMIFS(Табель_55!$J$2:$J$278,Табель_55!$D$2:$D$278,A17) | C17: =SUMIFS(Без_рядків!$H$2:$H$67,Без_рядків!$D$2:$D$67,A17) | D17: =B17+C17 | E17: =SUMIFS(Табель_55!$M$2:$M$278,Табель_55!$D$2:$D$278,A17) | F17: =SUMIFS(Без_рядків!$K$2:$K$67,Без_рядків!$D$2:$D$67,A17) | G17: =E17+F17
A18: 2023-09 | B18: =SUMIFS(Табель_55!$J$2:$J$278,Табель_55!$D$2:$D$278,A18) | C18: =SUMIFS(Без_рядків!$H$2:$H$67,Без_рядків!$D$2:$D$67,A18) | D18: =B18+C18 | E18: =SUMIFS(Табель_55!$M$2:$M$278,Табель_55!$D$2:$D$278,A18) | F18: =SUMIFS(Без_рядків!$K$2:$K$67,Без_рядків!$D$2:$D$67,A18) | G18: =E18+F18
A19: 2023-10 | B19: =SUMIFS(Табель_55!$J$2:$J$278,Табель_55!$D$2:$D$278,A19) | C19: =SUMIFS(Без_рядків!$H$2:$H$67,Без_рядків!$D$2:$D$67,A19) | D19: =B19+C19 | E19: =SUMIFS(Табель_55!$M$2:$M$278,Табель_55!$D$2:$D$278,A19) | F19: =SUMIFS(Без_рядків!$K$2:$K$67,Без_рядків!$D$2:$D$67,A19) | G19: =E19+F19
A20: 2023-11 | B20: =SUMIFS(Табель_55!$J$2:$J$278,Табель_55!$D$2:$D$278,A20) | C20: =SUMIFS(Без_рядків!$H$2:$H$67,Без_рядків!$D$2:$D$67,A20) | D20: =B20+C20 | E20: =SUMIFS(Табель_55!$M$2:$M$278,Табель_55!$D$2:$D$278,A20) | F20: =SUMIFS(Без_рядків!$K$2:$K$67,Без_рядків!$D$2:$D$67,A20) | G20: =E20+F20
A21: 2023-12 | B21: =SUMIFS(Табель_55!$J$2:$J$278,Табель_55!$D$2:$D$278,A21) | C21: =SUMIFS(Без_рядків!$H$2:$H$67,Без_рядків!$D$2:$D$67,A21) | D21: =B21+C21 | E21: =SUMIFS(Табель_55!$M$2:$M$278,Табель_55!$D$2:$D$278,A21) | F21: =SUMIFS(Без_рядків!$K$2:$K$67,Без_рядків!$D$2:$D$67,A21) | G21: =E21+F21
A22: 2024-01 | B22: =SUMIFS(Табель_55!$J$2:$J$278,Табель_55!$D$2:$D$278,A22) | C22: =SUMIFS(Без_рядків!$H$2:$H$67,Без_рядків!$D$2:$D$67,A22) | D22: =B22+C22 | E22: =SUMIFS(Табель_55!$M$2:$M$278,Табель_55!$D$2:$D$278,A22) | F22: =SUMIFS(Без_рядків!$K$2:$K$67,Без_рядків!$D$2:$D$67,A22) | G22: =E22+F22
A23: 2024-02 | B23: =SUMIFS(Табель_55!$J$2:$J$278,Табель_55!$D$2:$D$278,A23) | C23: =SUMIFS(Без_рядків!$H$2:$H$67,Без_рядків!$D$2:$D$67,A23) | D23: =B23+C23 | E23: =SUMIFS(Табель_55!$M$2:$M$278,Табель_55!$D$2:$D$278,A23) | F23: =SUMIFS(Без_рядків!$K$2:$K$67,Без_рядків!$D$2:$D$67,A23) | G23: =E23+F23
A24: 2024-03 | B24: =SUMIFS(Табель_55!$J$2:$J$278,Табель_55!$D$2:$D$278,A24) | C24: =SUMIFS(Без_рядків!$H$2:$H$67,Без_рядків!$D$2:$D$67,A24) | D24: =B24+C24 | E24: =SUMIFS(Табель_55!$M$2:$M$278,Табель_55!$D$2:$D$278,A24) | F24: =SUMIFS(Без_рядків!$K$2:$K$67,Без_рядків!$D$2:$D$67,A24) | G24: =E24+F24
... A55: 2026-10 | B55: =SUMIFS(Табель_55!$J$2:$J$278,Табель_55!$D$2:$D$278,A55) | C55: =SUMIFS(Без_рядків!$H$2:$H$67,Без_рядків!$D$2:$D$67,A55) | D55: =B55+C55 | E55: =SUMIFS(Табель_55!$M$2:$M$278,Табель_55!$D$2:$D$278,A55) | F55: =SUMIFS(Без_рядків!$K$2:$K$67,Без_рядків!$D$2:$D$67,A55) | G55: =E55+F55
A56: РАЗОМ | B56: =SUM(B13:B55) | C56: =SUM(C13:C55) | D56: =SUM(D13:D55) | E56: =SUM(E13:E55) | F56: =SUM(F13:F55) | G56: =SUM(G13:G55)
A58: Як читати
A59: • «Табель» — рядки проєкту 55, де фактичний час (td_actual_hours_amount) більший за виставлений (unit_amount): частково виставлені й безкоштовні (виставлено 0). Аркуш «Табель_55», кожен рядок з ID.
A60: • «Без рядків у табелі» — робота, яка видна в чаті, задачах Odoo, на зустрічах чи в документах, але не має жодного рядка в табелі. Оцінка консервативна, з джерелом. Аркуш «Без_рядків».
A61: • «Окремо (не в сумі)» — те, що не додаємо: роль керівників на зустрічах, непідтверджені зустрічі, гарантійні поступки, внутрішній онбординг #2930, рядки 0/0, дублі.
A62: • Не казати «завжди виставляли менше факту»: є 164,5 год ручних рядків без факту (переважно 2023). Коректно: «на рядках із фактом виставлено 513 год із 645».
A63: • Листопад 2023 оплачено актом на 11,5 год, хоча рядків табеля немає, — це не невиставлене.
A64: • Рядок 19528 (13.12.2023, 1 год) може бути оплачений актом за 12.2023 — див. примітку на аркуші «Табель_55».

Sheet Ставки
A1: Місяць | B1: Курс EUR, грн | C1: Ставка, грн/год | D1: Джерело
A2: 2023-04 | C2: =IF(B2="",1600,50*B2) | D2: до 04.2025 — 1600 грн/год
A3: 2023-05 | C3: =IF(B3="",1600,50*B3) | D3: до 04.2025 — 1600 грн/год
A4: 2023-06 | C4: =IF(B4="",1600,50*B4) | D4: до 04.2025 — 1600 грн/год
A5: 2023-07 | C5: =IF(B5="",1600,50*B5) | D5: до 04.2025 — 1600 грн/год
A6: 2023-08 | C6: =IF(B6="",1600,50*B6) | D6: до 04.2025 — 1600 грн/год
A7: 2023-09 | C7: =IF(B7="",1600,50*B7) | D7: до 04.2025 — 1600 грн/год
A8: 2023-10 | C8: =IF(B8="",1600,50*B8) | D8: до 04.2025 — 1600 грн/год
A9: 2023-11 | C9: =IF(B9="",1600,50*B9) | D9: до 04.2025 — 1600 грн/год
A10: 2023-12 | C10: =IF(B10="",1600,50*B10) | D10: до 04.2025 — 1600 грн/год
A11: 2024-01 | C11: =IF(B11="",1600,50*B11) | D11: до 04.2025 — 1600 грн/год
A12: 2024-02 | C12: =IF(B12="",1600,50*B12) | D12: до 04.2025 — 1600 грн/год
A13: 2024-03 | C13: =IF(B13="",1600,50*B13) | D13: до 04.2025 — 1600 грн/год
... A26: 2025-04 | C26: =IF(B26="",1600,50*B26) | D26: до 04.2025 — 1600 грн/год
A27: 2025-05 | B27: 46.93 | C27: =IF(B27="",1600,50*B27) | D27: курс прийнято 46,93 (як у звіті Q1)
A28: 2025-06 | B28: 46.9318 | C28: =IF(B28="",1600,50*B28) | D28: курс НБУ з res.currency.rate
A29: 2025-07 | B29: 47.9775 | C29: =IF(B29="",1600,50*B29) | D29: курс НБУ з res.currency.rate
A30: 2025-08 | B30: 49.0421 | C30: =IF(B30="",1600,50*B30) | D30: курс НБУ з res.currency.rate
A31: 2025-09 | B31: 48.0851 | C31: =IF(B31="",1600,50*B31) | D31: курс НБУ з res.currency.rate
A32: 2025-10 | B32: 48.8163 | C32: =IF(B32="",1600,50*B32) | D32: курс НБУ з res.currency.rate
A33: 2025-11 | B33: 48.4223 | C33: =IF(B33="",1600,50*B33) | D33: курс НБУ з res.currency.rate
A34: 2025-12 | B34: 48.7833 | C34: =IF(B34="",1600,50*B34) | D34: курс НБУ з res.currency.rate
A35: 2026-01 | B35: 50.981 | C35: =IF(B35="",1600,50*B35) | D35: курс із рахунків 2026
A36: 2026-02 | B36: 50.759 | C36: =IF(B36="",1600,50*B36) | D36: курс із рахунків 2026
A37: 2026-03 | B37: 50.474 | C37: =IF(B37="",1600,50*B37) | D37: курс із рахунків 2026
A38: 2026-04 | B38: 50.754 | C38: =IF(B38="",1600,50*B38) | D38: курс вересня 2026 (рахунку за місяць немає)
... A44: 2026-10 | B44: 50.754 | C44: =IF(B44="",1600,50*B44) | D44: курс вересня 2026
A46: Ставка з 05.2025 — 50 € без ПДВ (ДУ №3) × курс; до 04.2025 — 1600 грн/год. Сині комірки — вхідні дані.

Sheet Табель_55
A1: ID рядка | B1: Дата | C1: Рік | D1: Місяць | E1: Співробітник | F1: Задача | G1: Опис рядка | H1: Виставлено, год | I1: Факт, год | J1: Не виставлено, год | K1: Тип | L1: Ставка, грн/год | M1: Сума, грн | N1: Примітка
A2: 19528 | B2: 2023-12-13 | C2: 2023 | D2: 2023-12 | E2: Фіголь Дмитро | F2: Зустріч із клієнтом | G2: Зустріч із клієнтом | H2: 0 | I2: 1 | J2: =I2-H2 | K2: безкоштовно (виставлено 0) | L2: =INDEX(Ставки!$C$2:$C$44,MATCH(D2,Ставки!$A$2:$A$44,0)) | M2: =J2*L2 | N2: зустріч 13.12.2023; в акті за 12.2023 є 1 год за зустріч — можливо, оплачено
A3: 19618 | B3: 2023-12-15 | C3: 2023 | D3: 2023-12 | E3: Пусташинський Юрій | F3: Вилучити баг по уповновеженим в проектах | G3: / | H3: 1 | I3: 1.5 | J3: =I3-H3 | K3: частково виставлено | L3: =INDEX(Ставки!$C$2:$C$44,MATCH(D3,Ставки!$A$2:$A$44,0)) | M3: =J3*L3
A4: 19630 | B4: 2023-12-15 | C4: 2023 | D4: 2023-12 | E4: Пусташинський Юрій | F4: Винести СмартБатон в задачі | G4: / | H4: 2 | I4: 3 | J4: =I4-H4 | K4: частково виставлено | L4: =INDEX(Ставки!$C$2:$C$44,MATCH(D4,Ставки!$A$2:$A$44,0)) | M4: =J4*L4
A5: 19932 | B5: 2023-12-29 | C5: 2023 | D5: 2023-12 | E5: Фіголь Дмитро | F5: Налаштувати деталізацію прав користувача | G5: тест | H5: 0 | I5: 0.5 | J5: =I5-H5 | K5: безкоштовно (виставлено 0) | L5: =INDEX(Ставки!$C$2:$C$44,MATCH(D5,Ставки!$A$2:$A$44,0)) | M5: =J5*L5 | N5: зустріч 29.12.2023
A6: 20554 | B6: 2024-01-15 | C6: 2024 | D6: 2024-01 | E6: Адаменко Олесь | F6: Питання - відповіді | G6: Чи є доступ до редагування прав доступу у звичайних користувачів | H6: 0.25 | I6: 0.35 | J6: =I6-H6 | K6: частково виставлено | L6: =INDEX(Ставки!$C$2:$C$44,MATCH(D6,Ставки!$A$2:$A$44,0)) | M6: =J6*L6
A7: 20557 | B7: 2024-01-16 | C7: 2024 | D7: 2024-01 | E7: Адаменко Олесь | F7: Питання - відповіді | G7: Підготовка до зустрічі: коментування файлу з проблемами та побажаннями | H7: 0.25 | I7: 0.4 | J7: =I7-H7 | K7: частково виставлено | L7: =INDEX(Ставки!$C$2:$C$44,MATCH(D7,Ставки!$A$2:$A$44,0)) | M7: =J7*L7
A8: 20558 | B8: 2024-01-16 | C8: 2024 | D8: 2024-01 | E8: Адаменко Олесь | F8: Питання - відповіді | G8: Зустріч з LuxSite | H8: 0.75 | I8: 0.7833 | J8: =I8-H8 | K8: частково виставлено | L8: =INDEX(Ставки!$C$2:$C$44,MATCH(D8,Ставки!$A$2:$A$44,0)) | M8: =J8*L8
A9: 20564 | B9: 2024-01-17 | C9: 2024 | D9: 2024-01 | E9: Адаменко Олесь | F9: Помилка: Налаштування підзавдань у проектах | G9: Оцінка ризиків | H9: 0.25 | I9: 0.3333 | J9: =I9-H9 | K9: частково виставлено | L9: =INDEX(Ставки!$C$2:$C$44,MATCH(D9,Ставки!$A$2:$A$44,0)) | M9: =J9*L9
A10: 20571 | B10: 2024-01-17 | C10: 2024 | D10: 2024-01 | E10: Адаменко Олесь | F10: Питання - відповіді | G10: Проблеми з доменом зі сторони замовника | H10: 1.5 | I10: 1.5333 | J10: =I10-H10 | K10: частково виставлено | L10: =INDEX(Ставки!$C$2:$C$44,MATCH(D10,Ставки!$A$2:$A$44,0)) | M10: =J10*L10
A11: 20575 | B11: 2024-01-18 | C11: 2024 | D11: 2024-01 | E11: Адаменко Олесь | F11: Питання - відповіді | G11: Тестування можливостей інформування при зміні стадії | H11: 0.25 | I11: 0.3667 | J11: =I11-H11 | K11: частково виставлено | L11: =INDEX(Ставки!$C$2:$C$44,MATCH(D11,Ставки!$A$2:$A$44,0)) | M11: =J11*L11
A12: 20573 | B12: 2024-01-19 | C12: 2024 | D12: 2024-01 | E12: Адаменко Олесь | F12: Питання - відповіді | G12: Проблеми з повідомленнями у Марини Кот | H12: 0 | I12: 0.1167 | J12: =I12-H12 | K12: безкоштовно (виставлено 0) | L12: =INDEX(Ставки!$C$2:$C$44,MATCH(D12,Ставки!$A$2:$A$44,0)) | M12: =J12*L12
A13: 20572 | B13: 2024-01-22 | C13: 2024 | D13: 2024-01 | E13: Адаменко Олесь | F13: Питання - відповіді | G13: Підготовка до зустрічі: коментування файлу з проблемами та побажаннями | H13: 0.5 | I13: 0.5167 | J13: =I13-H13 | K13: частково виставлено | L13: =INDEX(Ставки!$C$2:$C$44,MATCH(D13,Ставки!$A$2:$A$44,0)) | M13: =J13*L13
A14: 20577 | B14: 2024-01-22 | C14: 2024 | D14: 2024-01 | E14: Адаменко Олесь | F14: Питання - відповіді | G14: Зустріч з LuxSite | H14: 0.5 | I14: 0.5333 | J14: =I14-H14 | K14: частково виставлено | L14: =INDEX(Ставки!$C$2:$C$44,MATCH(D14,Ставки!$A$2:$A$44,0)) | M14: =J14*L14
A15: 20520 | B15: 2024-01-23 | C15: 2024 | D15: 2024-01 | E15: Адаменко Олесь | F15: Допрацювання: Автоматичне додавання заявок з сайту в CRM | G15: Постановка задачі | H15: 0.5 | I15: 0.6167 | J15: =I15-H15 | K15: частково виставлено | L15: =INDEX(Ставки!$C$2:$C$44,MATCH(D15,Ставки!$A$2:$A$44,0)) | M15: =J15*L15
A16: 20589 | B16: 2024-01-24 | C16: 2024 | D16: 2024-01 | E16: Адаменко Олесь | F16: Щотижнева зустріч з замовником 17.01-31.01 | G16: Протокол зустрічі | H16: 1.25 | I16: 1.4167 | J16: =I16-H16 | K16: частково виставлено | L16: =INDEX(Ставки!$C$2:$C$44,MATCH(D16,Ставки!$A$2:$A$44,0)) | M16: =J16*L16
A17: 20600 | B17: 2024-01-24 | C17: 2024 | D17: 2024-01 | E17: Адаменко Олесь | F17: Помилка: Налаштування підзавдань у проектах | G17: Тестування проблеми та опис | H17: 0.25 | I17: 0.3667 | J17: =I17-H17 | K17: частково виставлено | L17: =INDEX(Ставки!$C$2:$C$44,MATCH(D17,Ставки!$A$2:$A$44,0)) | M17: =J17*L17
... A276: 81395 | B276: 2026-09-04 | C276: 2026 | D276: 2026-09 | E276: Адаменко Олесь | F276: Описати структуру роботи серверів Odoo | G276: Збір даних та сформовано опис. Передано на верифікацію відділу розробки | H276: 1.5 | I276: 1.7833 | J276: =I276-H276 | K276: частково виставлено | L276: =INDEX(Ставки!$C$2:$C$44,MATCH(D276,Ставки!$A$2:$A$44,0)) | M276: =J276*L276
A277: 82208 | B277: 2026-09-15 | C277: 2026 | D277: 2026-09 | E277: Станіславчук Олександр | F277: Виправлення: повернути можливість редагувати поле пріоритета проекту | G277: Внесення доробки в функціонал запису Проетів, поля Пріорітет | H277: 0 | I277: 1 | J277: =I277-H277 | K277: безкоштовно (виставлено 0) | L277: =INDEX(Ставки!$C$2:$C$44,MATCH(D277,Ставки!$A$2:$A$44,0)) | M277: =J277*L277 | N277: обнулено 02.10.2026
A278: 82949 | B278: 2026-09-22 | C278: 2026 | D278: 2026-09 | E278: Кутько Ігор | F278: Перенести оновлення на prod базу | G278: Оновлено сервер | H278: 0 | I278: 0.5 | J278: =I278-H278 | K278: безкоштовно (виставлено 0) | L278: =INDEX(Ставки!$C$2:$C$44,MATCH(D278,Ставки!$A$2:$A$44,0)) | M278: =J278*L278 | N278: обнулено 02.10.2026 (вересень — поступка)
A279: РАЗОМ | H279: =SUM(H2:H278) | I279: =SUM(I2:I278) | J279: =SUM(J2:J278) | M279: =SUM(M2:M278)

Sheet Без_рядків
A1: № | B1: Дата | C1: Рік | D1: Місяць | E1: Хто з ToDo | F1: Що зроблено | G1: Джерело | H1: Оцінка, год | I1: Впевненість | J1: Ставка, грн/год | K1: Сума, грн | L1: Примітка
A2: 1 | B2: 2023-05-11 | C2: 2023 | D2: 2023-05 | E2: Панков Євген / Бардаков | F2: Zoom-зустріч Discovery, запис у папку Discovery | G2: TG [11]–[19] | H2: 0.5 | I2: низька | J2: =INDEX(Ставки!$C$2:$C$44,MATCH(D2,Ставки!$A$2:$A$44,0)) | K2: =H2*J2 | L2: пресейл до договору
A3: 2 | B3: 2023-05-12 | C3: 2023 | D3: 2023-05 | E3: Панков Євген | F3: Структура папки Discovery, документ «Запит на надання інформації» | G3: TG [19]–[20] | H3: 0.5 | I3: низька | J3: =INDEX(Ставки!$C$2:$C$44,MATCH(D3,Ставки!$A$2:$A$44,0)) | K3: =H3*J3 | L3: пресейл до договору
A4: 3 | B4: 2023-05-16 | C4: 2023 | D4: 2023-05 | E4: Панков Євген | F4: Оновлення документа-запиту, нагадування клієнту | G4: TG [25]–[26] | H4: 0.25 | I4: низька | J4: =INDEX(Ставки!$C$2:$C$44,MATCH(D4,Ставки!$A$2:$A$44,0)) | K4: =H4*J4 | L4: пресейл до договору
A5: 4 | B5: 2023-05-17 | C5: 2023 | D5: 2023-05 | E5: Панков Євген | F5: Zoom-конференція з клієнтом | G5: TG [28] | H5: 0.5 | I5: низька | J5: =INDEX(Ставки!$C$2:$C$44,MATCH(D5,Ставки!$A$2:$A$44,0)) | K5: =H5*J5 | L5: пресейл до договору
A6: 5 | B6: 2023-06-01 | C6: 2023 | D6: 2023-06 | E6: Бардаков | F6: Консультація щодо обсягу CRM / управління проєктами | G6: TG [44]–[50] | H6: 0.25 | I6: низька | J6: =INDEX(Ставки!$C$2:$C$44,MATCH(D6,Ставки!$A$2:$A$44,0)) | K6: =H6*J6 | L6: пресейл до договору
A7: 6 | B7: 2023-06-02 | C7: 2023 | D7: 2023-06 | E7: Бардаков | F7: Таблиця «Перелік робіт» (оцінка) | G7: TG [52] | H7: 0.5 | I7: низька | J7: =INDEX(Ставки!$C$2:$C$44,MATCH(D7,Ставки!$A$2:$A$44,0)) | K7: =H7*J7 | L7: пресейл до договору
A8: 7 | B8: 2023-07-12 | C8: 2023 | D8: 2023-07 | E8: Єгамбердієва | F8: Зустріч з клієнтом | G8: TG [221], [234] | H8: 0.5 | I8: середня | J8: =INDEX(Ставки!$C$2:$C$44,MATCH(D8,Ставки!$A$2:$A$44,0)) | K8: =H8*J8
A9: 8 | B9: 2023-07-31 | C9: 2023 | D9: 2023-07 | E9: Єгамбердієва | F9: Доступ до демо-бази модуля діаграми Ганта | G9: TG [354] | H9: 0.25 | I9: середня | J9: =INDEX(Ставки!$C$2:$C$44,MATCH(D9,Ставки!$A$2:$A$44,0)) | K9: =H9*J9
A10: 9 | B10: 2023-09-01 | C10: 2023 | D10: 2023-09 | E10: Єгамбердієва | F10: Зустріч з клієнтом | G10: TG [729], [730] | H10: 0.5 | I10: середня | J10: =INDEX(Ставки!$C$2:$C$44,MATCH(D10,Ставки!$A$2:$A$44,0)) | K10: =H10*J10
A11: 10 | B11: 2023-09-05 | C11: 2023 | D11: 2023-09 | E11: Єгамбердієва | F11: Зустріч з клієнтом | G11: TG [738], [741] | H11: 0.25 | I11: середня | J11: =INDEX(Ставки!$C$2:$C$44,MATCH(D11,Ставки!$A$2:$A$44,0)) | K11: =H11*J11
A12: 11 | B12: 2023-09-13 | C12: 2023 | D12: 2023-09 | E12: Ніжніковський | F12: Підбір модуля діаграми Ганта, відповідь клієнту, пропозиція зібрати ТЗ | G12: TG [826], [839]–[846] | H12: 0.5 | I12: середня | J12: =INDEX(Ставки!$C$2:$C$44,MATCH(D12,Ставки!$A$2:$A$44,0)) | K12: =H12*J12
A13: 12 | B13: 2023-09-19 | C13: 2023 | D13: 2023-09 | E13: Ніжніковський | F13: Зустріч з клієнтом | G13: TG [861] | H13: 0.5 | I13: середня | J13: =INDEX(Ставки!$C$2:$C$44,MATCH(D13,Ставки!$A$2:$A$44,0)) | K13: =H13*J13
A14: 13 | B14: 2023-09-26 | C14: 2023 | D14: 2023-09 | E14: Єгамбердієва | F14: Навчання команди клієнта в Zoom, 12:00–13:00 | G14: TG [875]–[896] | H14: 1 | I14: середня | J14: =INDEX(Ставки!$C$2:$C$44,MATCH(D14,Ставки!$A$2:$A$44,0)) | K14: =H14*J14
A15: 14 | B15: 2023-10-03 | C15: 2023 | D15: 2023-10 | E15: Ніжніковський | F15: Доступ до папки із записами зустрічей | G15: TG [899]–[903] | H15: 0.25 | I15: середня | J15: =INDEX(Ставки!$C$2:$C$44,MATCH(D15,Ставки!$A$2:$A$44,0)) | K15: =H15*J15
A16: 15 | B16: 2023-10-11 | C16: 2023 | D16: 2023-10 | E16: Фіголь Дмитро | F16: Аналіз відповідей розробників модуля Ганта на питання клієнта | G16: TG [940]–[944] | H16: 0.75 | I16: середня | J16: =INDEX(Ставки!$C$2:$C$44,MATCH(D16,Ставки!$A$2:$A$44,0)) | K16: =H16*J16
A17: 16 | B17: 2023-10-13 | C17: 2023 | D17: 2023-10 | E17: Фіголь Дмитро | F17: Zoom-зустріч з клієнтом («маю десь годину») | G17: TG [946]–[957] | H17: 1 | I17: середня | J17: =INDEX(Ставки!$C$2:$C$44,MATCH(D17,Ставки!$A$2:$A$44,0)) | K17: =H17*J17
A18: 17 | B18: 2023-10-24 | C18: 2023 | D18: 2023-10 | E18: Фіголь Дмитро | F18: Зустріч з клієнтом | G18: TG [970], [974] | H18: 0.5 | I18: середня | J18: =INDEX(Ставки!$C$2:$C$44,MATCH(D18,Ставки!$A$2:$A$44,0)) | K18: =H18*J18 | L18: того ж дня є ручний рядок «Тестування» 1 год — інша тема
A19: 18 | B19: 2023-12-04 | C19: 2023 | D19: 2023-12 | E19: Фіголь Дмитро | F19: Роз'яснення щодо видалених / об'єднаних прав | G19: TG [1070]–[1072] | H19: 0.25 | I19: середня | J19: =INDEX(Ставки!$C$2:$C$44,MATCH(D19,Ставки!$A$2:$A$44,0)) | K19: =H19*J19
A20: 19 | B20: 2023-12-05 | C20: 2023 | D20: 2023-12 | E20: Фіголь Дмитро | F20: Доступ до відео навчання | G20: TG [1074]–[1090] | H20: 0.25 | I20: висока | J20: =INDEX(Ставки!$C$2:$C$44,MATCH(D20,Ставки!$A$2:$A$44,0)) | K20: =H20*J20
A21: 20 | B21: 2024-01-23 | C21: 2024 | D21: 2024-01 | E21: Кутько Ігор | F21: Оцінка задачі 2921 | G21: Odoo msg 83922 | H21: 0.25 | I21: середня | J21: =INDEX(Ставки!$C$2:$C$44,MATCH(D21,Ставки!$A$2:$A$44,0)) | K21: =H21*J21
A22: 21 | B22: 2024-05-16 | C22: 2024 | D22: 2024-05 | E22: Кутько Ігор | F22: Копія прод → тест, задача 4193 | G22: Odoo msg 159443, 159579, 159581 | H22: 0.5 | I22: середня | J22: =INDEX(Ставки!$C$2:$C$44,MATCH(D22,Ставки!$A$2:$A$44,0)) | K22: =H22*J22
A23: 22 | B23: 2024-06-11 | C23: 2024 | D23: 2024-06 | E23: Адаменко Олесь | F23: «Стратегічна сесія» з клієнтом | G23: календар; у Шаталюка 0,5 год є, в Адаменка немає | H23: 0.5 | I23: середня | J23: =INDEX(Ставки!$C$2:$C$44,MATCH(D23,Ставки!$A$2:$A$44,0)) | K23: =H23*J23
A24: 23 | B24: 2024-07-18 | C24: 2024 | D24: 2024-07 | E24: Кутько Ігор | F24: Вивантаження прод → тест, задача 4842 | G24: Odoo msg 303930, 303932, 306300 | H24: 0.5 | I24: середня | J24: =INDEX(Ставки!$C$2:$C$44,MATCH(D24,Ставки!$A$2:$A$44,0)) | K24: =H24*J24
A25: 24 | B25: 2024-07-24 | C25: 2024 | D25: 2024-07 | E25: Адаменко Олесь | F25: Зустріч з клієнтом | G25: TG [1450], [1451]; у Шаталюка 0,5 год є | H25: 0.5 | I25: середня | J25: =INDEX(Ставки!$C$2:$C$44,MATCH(D25,Ставки!$A$2:$A$44,0)) | K25: =H25*J25
A26: 25 | B26: 2024-07-29 | C26: 2024 | D26: 2024-07 | E26: Адаменко Олесь | F26: Доступ до інструкції з виставлення рахунків | G26: TG [1460] | H26: 0.25 | I26: висока | J26: =INDEX(Ставки!$C$2:$C$44,MATCH(D26,Ставки!$A$2:$A$44,0)) | K26: =H26*J26
A27: 26 | B27: 2024-11-15 | C27: 2024 | D27: 2024-11 | E27: Адаменко Олесь | F27: Статусна зустріч + протокол і документ «Питання по упр обліку» | G27: Drive «Протокол зустрічі LuxSite - 15.11.2024» | H27: 1 | I27: висока | J27: =INDEX(Ставки!$C$2:$C$44,MATCH(D27,Ставки!$A$2:$A$44,0)) | K27: =H27*J27 | L27: у Адаменка немає рядків 13–25.11.2024
A28: 27 | B28: 2024-11-18 | C28: 2024 | D28: 2024-11 | E28: Адаменко Олесь | F28: Перепроведення відпусток після зміни базових прав | G28: TG [1659]–[1663], [1719] | H28: 0.5 | I28: середня | J28: =INDEX(Ставки!$C$2:$C$44,MATCH(D28,Ставки!$A$2:$A$44,0)) | K28: =H28*J28
A29: 28 | B29: 2025-03-10 | C29: 2025 | D29: 2025-03 | E29: Адаменко Олесь | F29: Інструкція масової зміни стадії задач (10–11.03) | G29: TG [2012]–[2020], [2055]–[2056] | H29: 0.5 | I29: висока | J29: =INDEX(Ставки!$C$2:$C$44,MATCH(D29,Ставки!$A$2:$A$44,0)) | K29: =H29*J29
A30: 29 | B30: 2025-03-13 | C30: 2025 | D30: 2025-03 | E30: Адаменко Олесь | F30: Консультація: логіка лід → контакт → КП | G30: TG [2095]–[2096] | H30: 0.5 | I30: висока | J30: =INDEX(Ставки!$C$2:$C$44,MATCH(D30,Ставки!$A$2:$A$44,0)) | K30: =H30*J30
A31: 30 | B31: 2025-03-27 | C31: 2025 | D31: 2025-03 | E31: Драгунов Сергій | F31: Розширено права на рахунки для користувача | G31: TG [2160] | H31: 0.25 | I31: висока | J31: =INDEX(Ставки!$C$2:$C$44,MATCH(D31,Ставки!$A$2:$A$44,0)) | K31: =H31*J31
A32: 31 | B32: 2025-04-30 | C32: 2025 | D32: 2025-04 | E32: Кутько Ігор | F32: Оновлення проду, задача 9200 | G32: Odoo msg 587548 | H32: 0.25 | I32: висока | J32: =INDEX(Ставки!$C$2:$C$44,MATCH(D32,Ставки!$A$2:$A$44,0)) | K32: =H32*J32
A33: 32 | B33: 2025-05-07 | C33: 2025 | D33: 2025-05 | E33: Кутько Ігор | F33: Оновлення тесту, задача 9543 | G33: Odoo msg 593523 | H33: 0.25 | I33: висока | J33: =INDEX(Ставки!$C$2:$C$44,MATCH(D33,Ставки!$A$2:$A$44,0)) | K33: =H33*J33
A34: 33 | B34: 2025-05-15 | C34: 2025 | D34: 2025-05 | E34: Кутько Ігор | F34: Два оновлення проду, задачі 9982 і 9976 | G34: Odoo msg 598671, 598840 | H34: 0.5 | I34: висока | J34: =INDEX(Ставки!$C$2:$C$44,MATCH(D34,Ставки!$A$2:$A$44,0)) | K34: =H34*J34
A35: 34 | B35: 2025-05-20 | C35: 2025 | D35: 2025-05 | E35: Кутько Ігор | F35: Оновлення проду, задача 9977 | G35: Odoo msg 601523 | H35: 0.25 | I35: висока | J35: =INDEX(Ставки!$C$2:$C$44,MATCH(D35,Ставки!$A$2:$A$44,0)) | K35: =H35*J35
A36: 35 | B36: 2025-06-09 | C36: 2025 | D36: 2025-06 | E36: Драгунов Сергій | F36: Консультація: витрати ЗП у проєктах, звіт маржі | G36: TG [2430]–[2434] | H36: 0.5 | I36: висока | J36: =INDEX(Ставки!$C$2:$C$44,MATCH(D36,Ставки!$A$2:$A$44,0)) | K36: =H36*J36
A37: 36 | B37: 2025-06-24 | C37: 2025 | D37: 2025-06 | E37: Драгунов Сергій | F37: Пояснення: меню видно лише в режимі розробника | G37: TG [2492] | H37: 0.25 | I37: висока | J37: =INDEX(Ставки!$C$2:$C$44,MATCH(D37,Ставки!$A$2:$A$44,0)) | K37: =H37*J37
A38: 37 | B38: 2025-06-30 | C38: 2025 | D38: 2025-06 | E38: Скабіцька | F38: Зустріч з клієнтом (Адаменко і Грицюк записали по 0,5 год) | G38: календар 4692872, TG [2506] | H38: 0.5 | I38: середня | J38: =INDEX(Ставки!$C$2:$C$44,MATCH(D38,Ставки!$A$2:$A$44,0)) | K38: =H38*J38
A39: 38 | B39: 2025-07-07 | C39: 2025 | D39: 2025-07 | E39: Волохов Максим | F39: Пояснення причини зникнення сповіщень | G39: TG [2539] | H39: 0.25 | I39: висока | J39: =INDEX(Ставки!$C$2:$C$44,MATCH(D39,Ставки!$A$2:$A$44,0)) | K39: =H39*J39
... A55: 54 | B55: 2025-12-17 | C55: 2025 | D55: 2025-12 | E55: Пусташинський Юрій | F55: Оновлення модуля на проді, задача 12149 | G55: Odoo msg 762167 | H55: 0.25 | I55: висока | J55: =INDEX(Ставки!$C$2:$C$44,MATCH(D55,Ставки!$A$2:$A$44,0)) | K55: =H55*J55
...

Sheet Окремо (не в сумі)
A1: Дата | B1: Хто | C1: Що | D1: Джерело | E1: Год (≈) | F1: Чому не в сумі
A2: 2024-01-16 | B2: Адаменко Олесь | C2: Внутрішній проєкт 94, задача #2930 «Передача проекту LuxSite»: вхід нового менеджера | D2: Odoo рядок 20576 | E2: 8 | F2: ToDo взяла на себе; перенесено з проєкту LuxSite 29.01.2024
A3: 2026-06-05 … 2026-09-04 | B3: Львов Юрій | C3: Присутність на 5 зустрічах 2026 року (05.06, 22.06, 07.08, 18.08, 04.09) | D3: Fathom, календар | E3: 4.24 | F3: роль керівника, у проєкті 55 жодного рядка
A4: 2026-09-04 | B4: Джошкун | C4: Присутність на зустрічі 04.09 | D4: Fathom 179941955 | E4: 0.73 | F4: роль керівника
A5: 2025-01 … 2025-07 | B5: Скабіцька | C5: ≈14 зустрічей у календарі | D5: календар | E5: 9.5 | F5: факт проведення не підтверджено; оцінка 9–10 год
A6: 2025-07 … 2026-05 | B6: Анна / Львов | C6: Щомісячні звіти по табелюванню (≈10 звітів) | D6: TG [2530], [2544], [2710], [2849], [2899] | E6: 2.5 | F6: не оцінювали детально
A7: 2025-11-17 … 21 | B7: Драгунов Сергій | C7: Гарантійні виправлення по виписках | D7: TG [2753]–[2781] | E7: 1.75 | F7: свідома поступка: «За це рахунок не виставляється» [2777]
A8: 2024-10-09 … 11 | B8: Кутько Ігор | C8: Перша невдала спроба перенесення сервера | D8: календар 1620777, TG [1599]–[1606] | E8: 1 | F8: частково є в табелі (10.10 і 12.10), тому з суми виключено
A9: 2024-01-05 | B9: Ніжніковський | C9: Зустріч з клієнтом | D9: TG [1136], [1147] | E9: 0.5 | F9: того ж дня є оплачений рядок 0,5 год, тому з суми виключено
A10: 2023-12-29 | B10: Фіголь Дмитро | C10: Зустріч 11:00 + таблиця | D10: TG [1127] | E10: 0.5 | F10: уже є в табелі (рядок 19932, факт 0,5 / виставлено 0), не дублюємо
A11: 2026-01-27 | B11: Грицюк (сисадмін) | C11: Проєкт HR, рядок «Люкс сайт» | D11: Odoo | E11: 0.5 | F11: суть не описана
A12: — | B12: — | C12: Адміністрування тестового сервера | D12: TG [3115] | F12: «за свій рахунок», години не записувались
A13: 2023-11 | B13: Фіголь Дмитро та ін. | C13: Листопад 2023: перенесення на прод, навчання 02.11, правки прав | D13: акт 11.2023 (11,5 год) | F13: ОПЛАЧЕНО актом, рядків табеля немає — не невиставлене
A14: 2026-09-15 | B14: Іванюк Назарій | C14: Рядок табеля 0 / 0: Протестував, після внесення правок розробником | D14: Odoo рядок 82770 | F14: робота записана, години не проставлені
A15: 2026-09-15 | B15: Іванюк Назарій | C15: Рядок табеля 0 / 0: Описав та поставив задачу поверненню можливості постановки пріоритету проекту | D15: Odoo рядок 82769 | F15: робота записана, години не проставлені
A16: 2026-06-26 | B16: Адаменко Олесь | C16: Рядок табеля 0 / 0: Перепідв'язати задачі до вірного елемента замовлення на продаж | D16: Odoo рядок 73553 | F16: робота записана, години не проставлені
A17: 2026-06-23 | B17: Адаменко Олесь | C17: Рядок табеля 0 / 0: Менеджмент проекту | D17: Odoo рядок 73226 | F17: робота записана, години не проставлені
A18: 2025-12-16 | B18: Волохов Максим | C18: Рядок табеля 0 / 0: Було проведено анаіз даного питання та по роботі системи необхідно брати 2 окремі відпустк | D18: Odoo рядок 57652 | F18: робота записана, години не проставлені
A19: 2025-10-01 | B19: Лемешевський Ілля | C19: Рядок табеля 0 / 0: / | D19: Odoo рядок 52402 | F19: робота записана, години не проставлені
A20: 2025-06-03 | B20: Адаменко Олесь | C20: Рядок табеля 0 / 0: Управління проектом | D20: Odoo рядок 45265 | F20: робота записана, години не проставлені
A21: 2024-12-06 | B21: Волохов Максим | C21: Рядок табеля 0 / 0: Проаналізовано чому надійшов з невірною задачею. Відповідь проблеми зі сторони Odoo не зна | D21: Odoo рядок 34974 | F21: робота записана, години не проставлені
